Workbook
Name Slicer_Department: #N/A
Name Slicer_Department1: #N/A
Name Slicer_Job_Level: #N/A
Name Slicer_Overtime: #N/A

Sheet Sheet1
A3: Row Labels
A4: Human Resources
A5: Operations
A6: Technology
A7: Data & Analytics
A8: Finance
A9: Human Resources
A10: IT Support
A11: Operations
A12: Sales
A13: Technology
A14: Grand Total

Sheet HR_Dashboard
A1: TECHNOVA SOLUTIONS
A2: HR_ATTRITION & WORKFORCE ANALYSIS
A3: Workforce Overview | Attrition Patterns | 2025
A5: TOTAL EMPLOYEES | E5: ACTIVE EMPLOYEES | I5: EMPLOYEES WHO LEFT | M5: ATTRITION RATE | Q5: AVG AGE
A7: =GETPIVOTDATA("Count of Employee_ID",HR_Analysis!$D$4) -> 1500 | E7: =GETPIVOTDATA("Count of Employee_ID",HR_Analysis!$D$4,"Attrition","No") -> 1262 | I7: =GETPIVOTDATA("Count of Employee_ID",HR_Analysis!$D$4,"Attrition","Yes") -> 238 | M7: =GETPIVOTDATA("Average of Attrition_Flag",HR_Analysis!$D$4) -> 0.15866667 | Q7: =GETPIVOTDATA("Average of Age",HR_Analysis!$D$4) -> 33.3
A49: KEY FINDINGS
A52: • Attrition rate is 15.87% across 1,500 employees. | L52: • Sales department shows 20.62% attrition.
A53: • Employees with less than 1 year tenure show 27.81% attrition. | L53: • 80K–99K salary band shows 18.32% attrition.
A54: • Sales Executives show 26.67% attrition, above the overall rate. | L54: • Overtime employees show 16.63% vs 15.58% without overtime.
A55: • Employees aged 18–25 show 23.04% attrition. | L55: • Finance shows 13.24% attrition.
A56: • Job Satisfaction Level 2 shows 21.80% attrition. | L56: • Data & Analytics shows 13.76% attrition.
A59: Source: TechNova Solutions HR Workforce Dataset | Analysis Period: Jan–Dec 2025
A61: Note: Findings represent observed patterns in the dataset and should be considered areas for further investigation, not causal conclusions.

Sheet README
A1: TECHNOVA SOLUTIONS — HR ATTRITION ANALYSIS
A4: PROJECT OVERVIEW
A5: This project analyzes workforce and employee attrition data for TechNova Solutions using Microsoft Excel, Power Query, PivotTables, PivotCharts and interactive slicers. The objective is to identify observed attrition patterns across employee segments and provide evidence-based areas for further investigation.
A9: BUSINESS PROBLEM
A10: TechNova Solutions wants to use workforce data to understand employee attrition patterns and identify employee segments that may require further investigation by HR management.
A14: TOOLS & TECHNIQUES
A15: Microsoft Excel 2021
A16: Power Query
A17: PivotTables & PivotCharts
A18: Interactive Slicers
A19: Excel formulas and KPI calculations
A21: WORKBOOK STRUCTURE
A22: Sheet | B22: Purpose
A23: HR_Dashboard | B23: Interactive executive dashboard
A24: README | B24: Project overview and methodology
A25: HR_Findings | B25: Findings, implications and limitations
A26: HR_Analysis | B26: KPI calculations and analytical PivotTables
A27: Data_Quality_Check | B27: Data quality and validation checks
A28: Clean_HR_Data | B28: Power Query cleaned employee data
A29: Raw_HR_Data | B29: Original raw dataset
A30: Data_Dictionary | B30: Field definitions and descriptions
A32: ANALYTICAL METHODOLOGY
A33: Raw Data → Data Quality Assessment → Power Query Cleaning → Validation → KPI Calculation → Segmentation Analysis → PivotTables/PivotCharts → Interactive Dashboard → Findings

Sheet HR_Findings
A1: TECHNOVA SOLUTIONS — HR ATTRITION FINDINGS
A3: Analysis Period: Jan–Dec 2025 | Employees Analyzed: 1,500 | Overall Attrition: 15.87%
A7: Area | B7: Segment | C7: Employees | D7: Employees Left | E7: Attrition Rate | F7: Overall Rate | G7: Difference | H7: Interpretation
A8: Tenure | B8: <1 Year | C8: 187 | D8: 52 | E8: 0.2781 | F8: 0.1587 | G8: +11.94 pp | H8: Highest observed attrition among tenure bands.
A9: Job Role | B9: Sales Executive | C9: 45 | D9: 12 | E9: 0.2667 | F9: 0.1587 | G9: +10.80 pp | H9: Higher observed attrition than the overall dataset.
A10: Age Band | B10: 18–25 | C10: 191 | D10: 44 | E10: 0.2304 | F10: 0.1587 | G10: +7.17 pp | H10: Higher observed attrition than the overall dataset.
A11: Job Satisfaction | B11: Level 2 | C11: 179 | D11: 39 | E11: 0.218 | F11: 0.1587 | G11: +5.93 pp | H11: Higher observed attrition than the overall dataset.
A12: Department | B12: Sales | C12: 194 | D12: 40 | E12: 0.2062 | F12: 0.1587 | G12: +4.75 pp | H12: Highest observed attrition among departments.
A15: BUSINESS IMPLICATIONS & AREAS FOR FURTHER INVESTIGATION
A18: Area | B18: What the data suggests for further investigation
A19: Early Tenure | B19: Employees with less than 1 year tenure show 27.81% attrition. HR could examine onboarding, early-tenure experience and retention patterns for this group.
A20: Sales / Sales Executive | B20: Sales shows 20.62% attrition and Sales Executive shows 26.67%. HR could examine role-specific workload, career progression and retention patterns.
A21: Younger Employees | B21: Employees aged 18–25 show 23.04% attrition. HR could examine retention patterns and employee experience within this age group.
A22: Job Satisfaction | B22: Job Satisfaction Level 2 shows 21.80% attrition. HR could examine whether satisfaction-related patterns differ across departments, roles and tenure groups.
A25: ANALYSIS LIMITATIONS
A28: Limitation | B28: Explanation
A29: Synthetic Dataset | B29: The dataset is simulated for analytical and portfolio purposes and does not represent actual TechNova employee records.
A30: Observational Analysis | B30: The analysis identifies observed relationships and patterns but does not establish causation.
A31: Missing Values | B31: Some fields contain missing values; these were retained where appropriate or represented as Unknown during cleaning.
A32: Small Segments | B32: Some categories contain relatively few employees, so their attrition rates should be interpreted cautiously.

Sheet HR_Analysis
A1: HR Workforce & Attrition Analysis | D1: Column Labels
A2: Total Employees | B2: =COUNTA(tbl_HR_Clean[Employee_ID]) -> 1500 | D2: No | G2: Yes | J2: Total Average of Age | K2: Total Count of Employee_ID | L2: Total Average of Attrition_Flag
A3: Active Employees | B3: =COUNTIF(tbl_HR_Clean[Attrition],"No") -> 1262 | D3: Average of Age | E3: Count of Employee_ID | F3: Average of Attrition_Flag | G3: Average of Age | H3: Count of Employee_ID | I3: Average of Attrition_Flag
A4: Employees Who Left | B4: =COUNTIF(tbl_HR_Clean[Attrition],"Yes") -> 238 | D4: 33.395404 | E4: 1262 | F4: 0 | G4: 32.794118 | H4: 238 | I4: 1 | J4: 33.3 | K4: 1500 | L4: 0.15866667
A5: Attrition Rate | B5: =B4/B2 -> 0.15866667
A6: Average Age | B6: =AVERAGE(tbl_HR_Clean[Age]) -> 33.3
A7: Average Monthy Salary | B7: =AVERAGE(tbl_HR_Clean[Monthly_Salary]) -> 66657.333
D9: Count of Employee_ID | E9: Column Labels | I9: Count of Employee_ID | J9: Column Labels
A10: Attrition | B10: (All) | D10: Env Satisfaction | E10: No | F10: Yes | G10: Grand Total | I10: Row Labels | J10: No | K10: Yes | L10: Grand Total
D11: 1 | E11: 84 | F11: 14 | G11: 98 | I11: <40K | J11: 259 | K11: 55 | L11: 314
A12: Department | B12: Average of Attrition_Flag | D12: 2 | E12: 233 | F12: 48 | G12: 281 | I12: 100K+ | J12: 198 | K12: 38 | L12: 236
A13: Data & Analytics | B13: 0.13761468 | D13: 3 | E13: 607 | F13: 110 | G13: 717 | I13: 40K-59K | J13: 366 | K13: 60 | L13: 426
A14: Finance | B14: 0.13235294 | D14: 4 | E14: 334 | F14: 65 | G14: 399 | I14: 60K-79K | J14: 283 | K14: 50 | L14: 333
A15: Human Resources | B15: 0.16086957 | D15: (blank) | E15: 4 | F15: 1 | G15: 5 | I15: 80K-99K | J15: 156 | K15: 35 | L15: 191
A16: It Support | B16: 0.13888889 | D16: Grand Total | E16: 1262 | F16: 238 | G16: 1500 | I16: Grand Total | J16: 1262 | K16: 238 | L16: 1500
A17: Operations | B17: 0.17889908
A18: Sales | B18: 0.20618557
A19: Technology | B19: 0.15909091
A20: Grand Total | B20: 0.15866667 | I20: Attrition | J20: (All)
D21: Count of Employee_ID | E21: Column Labels
A22: Attrition | B22: (All) | D22: Job Satisfaction | E22: No | F22: Yes | G22: Grand Total | I22: Row Labels | J22: Average of Attrition_Flag
D23: 1 | E23: 102 | F23: 19 | G23: 121 | I23: <1 Year | J23: 0.27807487
A24: Row Labels | B24: Average of Attrition_Flag | D24: 2 | E24: 208 | F24: 58 | G24: 266 | I24: 1-3 Years | J24: 0.18808777
A25: 18-25 | B25: 0.23036649 | D25: 3 | E25: 609 | F25: 97 | G25: 706 | I25: 4-6 Years | J25: 0.13084112
A26: 26-35 | B26: 0.14756258 | D26: 4 | E26: 338 | F26: 63 | G26: 401 | I26: 7-10 Years | J26: 0.12106538
A27: 36-45 | B27: 0.14545455 | D27: (blank) | E27: 5 | F27: 1 | G27: 6 | I27: 11+ Years | J27: 0.13071895
A28: 46-55 | B28: 0.16666667 | D28: Grand Total | E28: 1262 | F28: 238 | G28: 1500 | I28: Grand Total | J28: 0.15866667
A29: Grand Total | B29: 0.1581054
A31: Attrition | B31: (All)
D32: Count of Employee_ID | E32: Column Labels
A33: Job Role | B33: Average of Attrition_Flag | D33: Overtime | E33: No | F33: Yes | G33: Grand Total
A34: Sales Executive | B34: 0.26666667 | D34: No | E34: 916 | F34: 169 | G34: 1085
A35: HR Analyst | B35: 0.26086957 | D35: Yes | E35: 346 | F35: 69 | G35: 415
A36: Process Associate | B36: 0.25 | D36: Grand Total | E36: 1262 | F36: 238 | G36: 1500
A37: Account Manager | B37: 0.22641509
A38: IT Support Specialist | B38: 0.22413793
A39: Grand Total | B39: 0.24418605

Sheet Data_Quality_Check
A1: raw rows | B1: =COUNTA(Raw_HR_Data!A:A)-1 -> 1506
A2: unique employees | B2: =SUMPRODUCT((Raw_HR_Data!A2:A1507<>"")/COUNTIF(Raw_HR_Data!A2:A1507,Raw_HR_Data!A2:A1507&"")) -> 1500
A3: duplicate employee IDs | B3: 6
A4: missing marital status | B4: =COUNTBLANK(Raw_HR_Data!G2:G1507) -> 12
A5: missing location | B5: =COUNTBLANK(Raw_HR_Data!L2:L1507) -> 8
A6: missing salary hike | B6: =COUNTBLANK(Raw_HR_Data!N2:N1507) -> 4
A7: missing job satisfaction | B7: =COUNTBLANK(Raw_HR_Data!R2:R1507) -> 6
A8: missing envornment satifaction | B8: =COUNTBLANK(Raw_HR_Data!S2:S1507) -> 5
A9: blank exit dates | B9: =COUNTBLANK(Raw_HR_Data!C2:C1507) -> 1268
A10: invalid exit dates | B10: =SUMPRODUCT(--(Raw_HR_Data!C2:C1507<Raw_HR_Data!B2:B1507),--(Raw_HR_Data!C2:C1507<>"")) -> 3
A11: department inconsistencies | B11: 1
A12: salary stored as text | B12: =SUMPRODUCT(--ISTEXT(Raw_HR_Data!M2:M1507)) -> 8

Sheet Clean_HR_Data
A1: Employee_ID | B1: Joining_Date | C1: Attrition | D1: Age | E1: Gender | F1: Marital_Status | G1: Education | H1: Department | I1: Job_Role | J1: Job_Level | K1: Location | L1: Monthly_Salary | M1: Salary_Hike_Pct | N1: Total_Work_Experience | O1: Years_at_Company | P1: Years_Since_Last_Promotion | Q1: Job_Satisfaction | R1: Environment_Satisfaction | S1: Work_Life_Balance | T1: Overtime | U1: Performance_Rating | V1: Exit_Date | W1: Age_Band | X1: Salary_Band | Y1: Tenure_Band | Z1: Attrition_Flag
A2: EMP0001 | B2: 44738 | C2: No | D2: 36 | E2: Non-Binary | F2: Divorced | G2: Bachelor's | H2: Operations | I2: Operations Executive | J2: 1 | K2: Chennai | L2: 30000 | M2: 11.6 | N2: 10.7 | O2: 3.5 | P2: 0.3 | Q2: 4 | R2: 3 | S2: 1 | T2: Yes | U2: 3 | W2: 36-45 | X2: <40K | Y2: 4-6 Years | Z2: 0
A3: EMP0002 | B3: 43610 | C3: No | D3: 31 | E3: Male | F3: Married | G3: Bachelor's | H3: Data & Analytics | I3: Data Engineer | J3: 2 | K3: Hyderabad | L3: 59000 | M3: 15.3 | N3: 12.2 | O3: 6.6 | P3: 2 | Q3: 1 | R3: 2 | S3: 4 | T3: No | U3: 3 | W3: 26-35 | X3: 40K-59K | Y3: 7-10 Years | Z3: 0
A4: EMP0003 | B4: 43053 | C4: No | D4: 30 | E4: Non-Binary | F4: Single | G4: Bachelor's | H4: It Support | I4: IT Analyst | J4: 3 | K4: Bengaluru | L4: 80000 | M4: 7.1 | N4: 11.2 | O4: 8.1 | P4: 3.3 | Q4: 3 | R4: 4 | S4: 3 | T4: No | U4: 4 | W4: 26-35 | X4: 80K-99K | Y4: 7-10 Years | Z4: 0
A5: EMP0004 | B5: 41703 | C5: No | D5: 35 | E5: Non-Binary | F5: Divorced | G5: Bachelor's | H5: Operations | I5: Operations Analyst | J5: 3 | K5: Chennai | L5: 55000 | M5: 2.1 | N5: 15.5 | O5: 11.8 | P5: 5 | Q5: 4 | R5: 2 | S5: 3 | T5: No | U5: 4 | W5: 26-35 | X5: 40K-59K | Y5: 11+ Years | Z5: 0
A6: EMP0005 | B6: 44801 | C6: No | D6: 26 | E6: Male | F6: Single | G6: Bachelor's | H6: Operations | I6: Operations Analyst | J6: 1 | K6: Hyderabad | L6: 34000 | M6: 5.4 | N6: 10.7 | O6: 3.3 | P6: 2.3 | Q6: 3 | R6: 2 | S6: 3 | T6: Yes | U6: 4 | W6: 26-35 | X6: <40K | Y6: 4-6 Years | Z6: 0
A7: EMP0006 | B7: 42011 | C7: No | D7: 43 | E7: Non-Binary | F7: Divorced | G7: Diploma | H7: Finance | I7: Finance Executive | J7: 1 | K7: Noida | L7: 33000 | M7: 9.3 | N7: 15 | O7: 11 | P7: 5.3 | Q7: 3 | R7: 3 | S7: 2 | T7: No | U7: 2 | W7: 36-45 | X7: <40K | Y7: 11+ Years | Z7: 0
A8: EMP0007 | B8: 44644 | C8: No | D8: 29 | E8: Female | F8: Divorced | G8: Bachelor's | H8: Human Resources | I8: HR Manager | J8: 4 | K8: Mumbai | L8: 107000 | M8: 4.4 | N8: 4.5 | O8: 3.8 | P8: 0.2 | Q8: 4 | R8: 2 | S8: 3 | T8: Yes | U8: 4 | W8: 26-35 | X8: 100K+ | Y8: 4-6 Years | Z8: 0
A9: EMP0008 | B9: 42827 | C9: No | D9: 29 | E9: Female | F9: Single | G9: PhD | H9: Finance | I9: Finance Manager | J9: 3 | K9: Bengaluru | L9: 77000 | M9: 6.6 | N9: 14.2 | O9: 8.7 | P9: 3.2 | Q9: 1 | R9: 3 | S9: 3 | T9: No | U9: 2 | W9: 26-35 | X9: 60K-79K | Y9: 7-10 Years | Z9: 0
A10: EMP0009 | B10: 42657 | C10: No | D10: 33 | E10: Non-Binary | F10: Single | G10: Diploma | H10: Operations | I10: Operations Manager | J10: 5 | K10: Mumbai | L10: 134000 | M10: 12.3 | N10: 15.9 | O10: 9.2 | P10: 3 | Q10: 2 | R10: 2 | S10: 3 | T10: No | U10: 2 | W10: 26-35 | X10: 100K+ | Y10: 7-10 Years | Z10: 0
A11: EMP0010 | B11: 42158 | C11: Yes | D11: 34 | E11: Male | F11: Single | G11: PhD | H11: Technology | I11: Software Developer | J11: 4 | K11: Chennai | L11: 107000 | M11: 3.7 | N11: 18 | O11: 10.4 | P11: 0.5 | Q11: 3 | R11: 3 | S11: 2 | T11: No | U11: 4 | V11: 45948 | W11: 26-35 | X11: 100K+ | Y11: 11+ Years | Z11: 1
A12: EMP0011 | B12: 43321 | C12: No | D12: 38 | E12: Non-Binary | F12: Married | G12: Bachelor's | H12: Data & Analytics | I12: Senior Data Analyst | J12: 3 | K12: Pune | L12: 91000 | M12: 8.5 | N12: 12.9 | O12: 7.4 | P12: 4.3 | Q12: 4 | R12: 3 | S12: 3 | T12: No | U12: 3 | W12: 36-45 | X12: 80K-99K | Y12: 7-10 Years | Z12: 0
A13: EMP0012 | B13: 45580 | C13: Yes | D13: 23 | E13: Non-Binary | F13: Single | G13: Diploma | H13: Data & Analytics | I13: Data Analyst | J13: 1 | K13: Noida | L13: 33000 | M13: 7.2 | N13: 6 | O13: 0.3 | P13: 0 | Q13: 2 | R13: 1 | S13: 1 | T13: No | U13: 3 | V13: 45694 | W13: 18-25 | X13: <40K | Y13: <1 Year | Z13: 1
A14: EMP0013 | B14: 42822 | C14: No | D14: 35 | E14: Female | F14: Married | G14: Bachelor's | H14: Finance | I14: Accountant | J14: 3 | K14: Noida | L14: 64000 | M14: 10.3 | N14: 12.5 | O14: 8.8 | P14: 2.4 | Q14: 3 | R14: 2 | S14: 3 | T14: No | U14: 3 | W14: 26-35 | X14: 60K-79K | Y14: 7-10 Years | Z14: 0
A15: EMP0014 | B15: 43865 | C15: No | D15: 28 | E15: Male | F15: Married | G15: Bachelor's | H15: Operations | I15: Operations Executive | J15: 1 | K15: Bengaluru | L15: 37000 | M15: 13.1 | N15: 10.2 | O15: 5.9 | P15: 0.8 | Q15: 2 | R15: 2 | S15: 3 | T15: No | U15: 5 | W15: 26-35 | X15: <40K | Y15: 4-6 Years | Z15: 0
A16: EMP0015 | B16: 43542 | C16: No | D16: 27 | E16: Female | F16: Married | G16: PhD | H16: Operations | I16: Operations Executive | J16: 1 | K16: Hyderabad | L16: 29000 | M16: 10.3 | N16: 10.7 | O16: 6.8 | P16: 1.3 | Q16: 4 | R16: 3 | S16: 1 | T16: No | U16: 3 | W16: 26-35 | X16: <40K | Y16: 7-10 Years | Z16: 0
A17: EMP0016 | B17: 44862 | C17: No | D17: 30 | E17: Male | F17: Single | G17: Bachelor's | H17: Finance | I17: Finance Manager | J17: 2 | K17: Pune | L17: 53000 | M17: 4.6 | N17: 9.2 | O17: 3.2 | P17: 0.2 | Q17: 3 | R17: 3 | S17: 3 | T17: No | U17: 4 | W17: 26-35 | X17: 40K-59K | Y17: 4-6 Years | Z17: 0
A18: EMP0017 | B18: 44908 | C18: No | D18: 39 | E18: Female | F18: Single | G18: Diploma | H18: Technology | I18: Software Developer | J18: 3 | K18: Pune | L18: 99000 | M18: 8.7 | N18: 7.8 | O18: 3 | P18: 1.9 | Q18: 4 | R18: 3 | S18: 3 | T18: Yes | U18: 4 | W18: 36-45 | X18: 80K-99K | Y18: 1-3 Years | Z18: 0
A19: EMP0018 | B19: 43154 | C19: No | D19: 36 | E19: Non-Binary | F19: Married | G19: Master's | H19: Sales | I19: Business Development Executive | J19: 2 | K19: Hyderabad | L19: 47000 | M19: 10.4 | N19: 7.9 | O19: 7.9 | P19: 3.7 | Q19: 4 | R19: 3 | S19: 2 | T19: No | U19: 4 | W19: 36-45 | X19: 40K-59K | Y19: 7-10 Years | Z19: 0
A20: EMP0019 | B20: 45239 | C20: No | D20: 33 | E20: Non-Binary | F20: Single | G20: Master's | H20: Technology | I20: Senior Software Developer | J20: 2 | K20: Hyderabad | L20: 73000 | M20: 0 | N20: 10 | O20: 2.1 | P20: 1.4 | Q20: 3 | R20: 1 | S20: 4 | T20: No | U20: 3 | W20: 26-35 | X20: 60K-79K | Y20: 1-3 Years | Z20: 0
A21: EMP0020 | B21: 45249 | C21: No | D21: 34 | E21: Male | F21: Single | G21: PhD | H21: Technology | I21: Software Developer | J21: 3 | K21: Hyderabad | L21: 84000 | M21: 9.4 | N21: 7.6 | O21: 2.1 | P21: 1.8 | Q21: 2 | R21: 3 | S21: 2 | T21: No | U21: 5 | W21: 26-35 | X21: 80K-99K | Y21: 1-3 Years | Z21: 0
A22: EMP0021 | B22: 45402 | C22: No | D22: 31 | E22: Male | F22: Divorced | G22: Bachelor's | H22: Technology | I22: Software Developer | J22: 2 | K22: Hyderabad | L22: 63000 | M22: 14.9 | N22: 7.3 | O22: 1.7 | P22: 1 | Q22: 2 | R22: 2 | S22: 4 | T22: No | U22: 4 | W22: 26-35 | X22: 60K-79K | Y22: 1-3 Years | Z22: 0
A23: EMP0022 | B23: 44861 | C23: No | D23: 27 | E23: Female | F23: Divorced | G23: PhD | H23: Human Resources | I23: Recruiter | J23: 1 | K23: Chennai | L23: 28000 | M23: 12.7 | N23: 11 | O23: 3.2 | P23: 0.1 | Q23: 3 | R23: 3 | S23: 3 | T23: Yes | U23: 4 | W23: 26-35 | X23: <40K | Y23: 4-6 Years | Z23: 0
A24: EMP0023 | B24: 45161 | C24: No | D24: 29 | E24: Non-Binary | F24: Divorced | G24: Master's | H24: Operations | I24: Operations Analyst | J24: 4 | K24: Hyderabad | L24: 108000 | M24: 9.4 | N24: 5.7 | O24: 2.4 | P24: 0.4 | Q24: 4 | R24: 4 | S24: 4 | T24: Yes | U24: 3 | W24: 26-35 | X24: 100K+ | Y24: 1-3 Years | Z24: 0
A25: EMP0024 | B25: 45804 | C25: No | D25: 28 | E25: Female | F25: Married | G25: Diploma | H25: Data & Analytics | I25: Data Analyst | J25: 2 | K25: Bengaluru | L25: 59000 | M25: 7.4 | N25: 3.4 | O25: 0.6 | P25: 0 | Q25: 2 | R25: 4 | S25: 2 | T25: No | U25: 4 | W25: 26-35 | X25: 40K-59K | Y25: <1 Year | Z25: 0
... A33: EMP0032 | B33: 43572 | C33: No | D33: 37 | E33: Non-Binary | F33: Single | G33: Diploma | H33: Human Resources | I33: HR Manager | J33: 4 | K33: Mumbai | L33: 126000 | M33: 5 | N33: 8.8 | O33: 6.7 | P33: 1.5 | Q33: 4 | R33: 3 | S33: 4 | T33: No | U33: 4 | W33: 36-45 | X33: 100K+ | Y33: 7-10 Years | Z33: 0
A34: EMP0033 | B34: 44478 | C34: Yes | D34: 34 | E34: Female | F34: Single | G34: Master's | H34: Technology | I34: QA Engineer | J34: 2 | K34: Mumbai | L34: 55000 | M34: 2.8 | N34: 9.3 | O34: 3.8 | P34: 2.7 | Q34: 2 | R34: 1 | S34: 3 | T34: No | U34: 4 | V34: 45854 | W34: 26-35 | X34: 40K-59K | Y34: 4-6 Years | Z34: 1
A35: EMP0034 | B35: 44129 | C35: Yes | D35: 26 | E35: Non-Binary | F35: Divorced | G35: Master's | H35: Finance | I35: Financial Analyst | J35: 1 | K35: Mumbai | L35: 39000 | M35: 5.3 | N35: 7.1 | O35: 4.7 | P35: 1.8 | Q35: 3 | R35: 4 | S35: 4 | T35: No | U35: 4 | V35: 45838 | W35: 26-35 | X35: <40K | Y35: 4-6 Years | Z35: 1
A36: EMP0035 | B36: 45831 | C36: No | D36: 28 | E36: Female | F36: Divorced | G36: Bachelor's | H36: Data & Analytics | I36: Senior Data Analyst | J36: 2 | K36: Bengaluru | L36: 59000 | M36: 12.3 | N36: 1.8 | O36: 0.5 | P36: 0 | Q36: 3 | R36: 2 | S36: 3 | T36: No | U36: 1 | W36: 26-35 | X36: 40K-59K | Y36: <1 Year | Z36: 0
A37: EMP0036 | B37: 43940 | C37: No | D37: 35 | E37: Female | F37: Single | G37: PhD | H37: Operations | I37: Process Associate | J37: 2 | K37: Bengaluru | L37: 61000 | M37: 2.6 | N37: 8.3 | O37: 5.7 | P37: 4.3 | Q37: 3 | R37: 3 | S37: 3 | T37: Yes | U37: 4 | W37: 26-35 | X37: 60K-79K | Y37: 4-6 Years | Z37: 0
A38: EMP0037 | B38: 44417 | C38: No | D38: 35 | E38: Male | F38: Married | G38: Bachelor's | H38: Operations | I38: Operations Executive | J38: 5 | K38: Chennai | L38: 151000 | M38: 4.1 | N38: 10.4 | O38: 4.4 | P38: 4.2 | Q38: 4 | R38: 2 | S38: 1 | T38: No | U38: 2 | W38: 26-35 | X38: 100K+ | Y38: 4-6 Years | Z38: 0
A39: EMP0038 | B39: 42636 | C39: No | D39: 37 | E39: Female | F39: Divorced | G39: PhD | H39: Data & Analytics | I39: Data Engineer | J39: 3 | K39: Mumbai | L39: 92000 | M39: 10 | N39: 10.2 | O39: 9.3 | P39: 4.9 | Q39: 3 | R39: 4 | S39: 2 | T39: Yes | U39: 1 | W39: 36-45 | X39: 80K-99K | Y39: 7-10 Years | Z39: 0
A40: EMP0039 | B40: 43971 | C40: No | D40: 28 | E40: Female | F40: Divorced | G40: PhD | H40: Operations | I40: Operations Analyst | J40: 1 | K40: Noida | L40: 34000 | M40: 10.2 | N40: 12.4 | O40: 5.6 | P40: 3.4 | Q40: 2 | R40: 2 | S40: 4 | T40: No | U40: 4 | W40: 26-35 | X40: <40K | Y40: 4-6 Years | Z40: 0
A41: EMP0040 | B41: 44455 | C41: Yes | D41: 46 | E41: Non-Binary | F41: Married | G41: PhD | H41: Sales | I41: Sales Executive | J41: 3 | K41: Mumbai | L41: 81000 | M41: 4.2 | N41: 8.9 | O41: 3.8 | P41: 3.1 | Q41: 4 | R41: 3 | S41: 3 | T41: No | U41: 4 | V41: 45843 | W41: 46-55 | X41: 80K-99K | Y41: 4-6 Years | Z41: 1
A42: EMP0041 | B42: 45242 | C42: No | D42: 26 | E42: Female | F42: Married | G42: Master's | H42: Finance | I42: Finance Executive | J42: 1 | K42: Mumbai | L42: 42000 | M42: 13.6 | N42: 5.7 | O42: 2.1 | P42: 1.6 | Q42: 4 | R42: 3 | S42: 3 | T42: Yes | U42: 3 | W42: 26-35 | X42: 40K-59K | Y42: 1-3 Years | Z42: 0
A43: EMP0042 | B43: 44459 | C43: No | D43: 40 | E43: Male | F43: Divorced | G43: PhD | H43: Data & Analytics | I43: Senior Data Analyst | J43: 3 | K43: Noida | L43: 93000 | M43: 12.3 | N43: 4.4 | O43: 4.3 | P43: 4.1 | Q43: 3 | R43: 2 | S43: 3 | T43: No | U43: 3 | W43: 36-45 | X43: 80K-99K | Y43: 4-6 Years | Z43: 0
A44: EMP0043 | B44: 45846 | C44: No | D44: 31 | E44: Non-Binary | F44: Married | G44: Diploma | H44: Operations | I44: Process Associate | J44: 2 | K44: Noida | L44: 43000 | M44: 5.4 | N44: 5.8 | O44: 0.5 | P44: 0 | Q44: 3 | R44: 3 | S44: 3 | T44: No | U44: 5 | W44: 26-35 | X44: 40K-59K | Y44: <1 Year | Z44: 0
A45: EMP0044 | B45: 44928 | C45: No | D45: 32 | E45: Non-Binary | F45: Divorced | G45: Diploma | H45: Finance | I45: Finance Executive | J45: 2 | K45: Bengaluru | L45: 58000 | M45: 10.1 | N45: 10.6 | O45: 3 | P45: 2.1 | Q45: 3 | R45: 2 | S45: 3 | T45: No | U45: 3 | W45: 26-35 | X45: 40K-59K | Y45: 1-3 Years | Z45: 0
A46: EMP0045 | B46: 44371 | C46: No | D46: 33 | E46: Female | F46: Single | G46: Bachelor's | H46: It Support | I46: System Administrator | J46: 2 | K46: Chennai | L46: 65000 | M46: 7.9 | N46: 4.9 | O46: 4.5 | P46: 0.2 | Q46: 3 | R46: 3 | S46: 4 | T46: No | U46: 4 | W46: 26-35 | X46: 60K-79K | Y46: 4-6 Years | Z46: 0
A47: EMP0046 | B47: 44457 | C47: No | D47: 37 | E47: Male | F47: Single | G47: Diploma | H47: Sales | I47: Business Development Executive | J47: 3 | K47: Bengaluru | L47: 69000 | M47: 4.7 | N47: 5.2 | O47: 4.3 | P47: 0.3 | Q47: 3 | R47: 3 | S47: 3 | T47: No | U47: 4 | W47: 36-45 | X47: 60K-79K | Y47: 4-6 Years | Z47: 0
...

Sheet Raw_HR_Data
A1: Employee_ID | B1: Joining_Date | C1: Exit_Date | D1: Attrition | E1: Age | F1: Gender | G1: Marital_Status | H1: Education | I1: Department | J1: Job_Role | K1: Job_Level | L1: Location | M1: Monthly_Salary | N1: Salary_Hike_Pct | O1: Total_Work_Experience | P1: Years_at_Company | Q1: Years_Since_Last_Promotion | R1: Job_Satisfaction | S1: Environment_Satisfaction | T1: Work_Life_Balance | U1: Overtime | V1: Performance_Rating | W1: Column1 | X1: Column2
A2: EMP0001 | B2: 44738 | D2: No | E2: 36 | F2: Non-Binary | G2: Divorced | H2: Bachelor's | I2: Operations | J2: Operations Executive | K2: 1 | L2: Chennai | M2: 30000 | N2: 11.6 | O2: 10.7 | P2: 3.5 | Q2: 0.3 | R2: 4 | S2: 3 | T2: 1 | U2: Yes | V2: 3 | W2: =COUNTIF($A$2:A2,A2) -> 1
A3: EMP0002 | B3: 43610 | D3: No | E3: 31 | F3: Male | G3: Married | H3: Bachelor's | I3: Data & Analytics | J3: Data Engineer | K3: 2 | L3: Hyderabad | M3: 59000 | N3: 15.3 | O3: 12.2 | P3: 6.6 | Q3: 2 | R3: 1 | S3: 2 | T3: 4 | U3: No | V3: 3 | W3: =COUNTIF($A$2:A3,A3) -> 1
A4: EMP0003 | B4: 43053 | D4: No | E4: 30 | F4: Non-Binary | G4: Single | H4: Bachelor's | I4: IT Support | J4: IT Analyst | K4: 3 | L4: Bengaluru | M4: 80000 | N4: 7.1 | O4: 11.2 | P4: 8.1 | Q4: 3.3 | R4: 3 | S4: 4 | T4: 3 | U4: No | V4: 4 | W4: =COUNTIF($A$2:A4,A4) -> 1
A5: EMP0004 | B5: 41703 | D5: No | E5: 35 | F5: Non-Binary | G5: Divorced | H5: Bachelor's | I5: Operations | J5: Operations Analyst | K5: 3 | L5: Chennai | M5: 55000 | N5: 2.1 | O5: 15.5 | P5: 11.8 | Q5: 5 | R5: 4 | S5: 2 | T5: 3 | U5: No | V5: 4 | W5: =COUNTIF($A$2:A5,A5) -> 1
A6: EMP0005 | B6: 44801 | D6: No | E6: 26 | F6: Male | G6: Single | H6: Bachelor's | I6: Operations | J6: Operations Analyst | K6: 1 | L6: Hyderabad | M6: 34000 | N6: 5.4 | O6: 10.7 | P6: 3.3 | Q6: 2.3 | R6: 3 | S6: 2 | T6: 3 | U6: Yes | V6: 4 | W6: =COUNTIF($A$2:A6,A6) -> 1
A7: EMP0006 | B7: 42011 | D7: No | E7: 43 | F7: Non-Binary | G7: Divorced | H7: Diploma | I7: Finance | J7: Finance Executive | K7: 1 | L7: Noida | M7: 33000 | N7: 9.3 | O7: 15 | P7: 11 | Q7: 5.3 | R7: 3 | S7: 3 | T7: 2 | U7: No | V7: 2 | W7: =COUNTIF($A$2:A7,A7) -> 1
A8: EMP0007 | B8: 44644 | D8: No | E8: 29 | F8: Female | G8: Divorced | H8: Bachelor's | I8: Human Resources | J8: HR Manager | K8: 4 | L8: Mumbai | M8: 107000 | N8: 4.4 | O8: 4.5 | P8: 3.8 | Q8: 0.2 | R8: 4 | S8: 2 | T8: 3 | U8: Yes | V8: 4 | W8: =COUNTIF($A$2:A8,A8) -> 1
A9: EMP0008 | B9: 42827 | D9: No | E9: 29 | F9: Female | G9: Single | H9: PhD | I9: Finance | J9: Finance Manager | K9: 3 | L9: Bengaluru | M9: 77000 | N9: 6.6 | O9: 14.2 | P9: 8.7 | Q9: 3.2 | R9: 1 | S9: 3 | T9: 3 | U9: No | V9: 2 | W9: =COUNTIF($A$2:A9,A9) -> 1
A10: EMP0009 | B10: 42657 | D10: No | E10: 33 | F10: Non-Binary | G10: Single | H10: Diploma | I10: Operations | J10: Operations Manager | K10: 5 | L10: Mumbai | M10: 134000 | N10: 12.3 | O10: 15.9 | P10: 9.2 | Q10: 3 | R10: 2 | S10: 2 | T10: 3 | U10: No | V10: 2 | W10: =COUNTIF($A$2:A10,A10) -> 1
A11: EMP0010 | B11: 42158 | C11: 45948 | D11: Yes | E11: 34 | F11: Male | G11: Single | H11: PhD | I11: Technology | J11: Software Developer | K11: 4 | L11: Chennai | M11: 107000 | N11: 3.7 | O11: 18 | P11: 10.4 | Q11: 0.5 | R11: 3 | S11: 3 | T11: 2 | U11: No | V11: 4 | W11: =COUNTIF($A$2:A11,A11) -> 1
A12: EMP0011 | B12: 43321 | D12: No | E12: 38 | F12: Non-Binary | G12: Married | H12: Bachelor's | I12: Data & Analytics | J12: Senior Data Analyst | K12: 3 | L12: Pune | M12: 91000 | N12: 8.5 | O12: 12.9 | P12: 7.4 | Q12: 4.3 | R12: 4 | S12: 3 | T12: 3 | U12: No | V12: 3 | W12: =COUNTIF($A$2:A12,A12) -> 1
A13: EMP0012 | B13: 45580 | C13: 45694 | D13: Yes | E13: 23 | F13: Non-Binary | G13: Single | H13: Diploma | I13: Data & Analytics | J13: Data Analyst | K13: 1 | L13: Noida | M13: 33000 | N13: 7.2 | O13: 6 | P13: 0.3 | Q13: 0 | R13: 2 | S13: 1 | T13: 1 | U13: No | V13: 3 | W13: =COUNTIF($A$2:A13,A13) -> 1
A14: EMP0013 | B14: 42822 | D14: No | E14: 35 | F14: Female | G14: Married | H14: Bachelor's | I14: Finance | J14: Accountant | K14: 3 | L14: Noida | M14: 64000 | N14: 10.3 | O14: 12.5 | P14: 8.8 | Q14: 2.4 | R14: 3 | S14: 2 | T14: 3 | U14: No | V14: 3 | W14: =COUNTIF($A$2:A14,A14) -> 1
A15: EMP0014 | B15: 43865 | D15: No | E15: 28 | F15: Male | G15: Married | H15: Bachelor's | I15: Operations | J15: Operations Executive | K15: 1 | L15: Bengaluru | M15: 37000 | N15: 13.1 | O15: 10.2 | P15: 5.9 | Q15: 0.8 | R15: 2 | S15: 2 | T15: 3 | U15: No | V15: 5 | W15: =COUNTIF($A$2:A15,A15) -> 1
A16: EMP0015 | B16: 43542 | D16: No | E16: 27 | F16: Female | G16: Married | H16: PhD | I16: Operations | J16: Operations Executive | K16: 1 | L16: Hyderabad | M16: 29000 | N16: 10.3 | O16: 10.7 | P16: 6.8 | Q16: 1.3 | R16: 4 | S16: 3 | T16: 1 | U16: No | V16: 3 | W16: =COUNTIF($A$2:A16,A16) -> 1
A17: EMP0016 | B17: 44862 | D17: No | E17: 30 | F17: Male | G17: Single | H17: Bachelor's | I17: Finance | J17: Finance Manager | K17: 2 | L17: Pune | M17: 53000 | N17: 4.6 | O17: 9.2 | P17: 3.2 | Q17: 0.2 | R17: 3 | S17: 3 | T17: 3 | U17: No | V17: 4 | W17: =COUNTIF($A$2:A17,A17) -> 1
A18: EMP0017 | B18: 44908 | D18: No | E18: 39 | F18: Female | G18: Single | H18: Diploma | I18: Technology | J18: Software Developer | K18: 3 | L18: Pune | M18: 99000 | N18: 8.7 | O18: 7.8 | P18: 3 | Q18: 1.9 | R18: 4 | S18: 3 | T18: 3 | U18: Yes | V18: 4 | W18: =COUNTIF($A$2:A18,A18) -> 1
A19: EMP0018 | B19: 43154 | D19: No | E19: 36 | F19: Non-Binary | G19: Married | H19: Master's | I19: Sales | J19: Business Development Executive | K19: 2 | L19: Hyderabad | M19: 47000 | N19: 10.4 | O19: 7.9 | P19: 7.9 | Q19: 3.7 | R19: 4 | S19: 3 | T19: 2 | U19: No | V19: 4 | W19: =COUNTIF($A$2:A19,A19) -> 1
A20: EMP0019 | B20: 45239 | D20: No | E20: 33 | F20: Non-Binary | G20: Single | H20: Master's | I20: Technology | J20: Senior Software Developer | K20: 2 | L20: Hyderabad | M20: 73000 | N20: 0 | O20: 10 | P20: 2.1 | Q20: 1.4 | R20: 3 | S20: 1 | T20: 4 | U20: No | V20: 3 | W20: =COUNTIF($A$2:A20,A20) -> 1
A21: EMP0020 | B21: 45249 | D21: No | E21: 34 | F21: Male | G21: Single | H21: PhD | I21: Technology | J21: Software Developer | K21: 3 | L21: Hyderabad | M21: 84000 | N21: 9.4 | O21: 7.6 | P21: 2.1 | Q21: 1.8 | R21: 2 | S21: 3 | T21: 2 | U21: No | V21: 5 | W21: =COUNTIF($A$2:A21,A21) -> 1
A22: EMP0021 | B22: 45402 | D22: No | E22: 31 | F22: Male | G22: Divorced | H22: Bachelor's | I22: Technology | J22: Software Developer | K22: 2 | L22: Hyderabad | M22: 63000 | N22: 14.9 | O22: 7.3 | P22: 1.7 | Q22: 1 | R22: 2 | S22: 2 | T22: 4 | U22: No | V22: 4 | W22: =COUNTIF($A$2:A22,A22) -> 1
A23: EMP0022 | B23: 44861 | D23: No | E23: 27 | F23: Female | G23: Divorced | H23: PhD | I23: Human Resources | J23: Recruiter | K23: 1 | L23: Chennai | M23: 28000 | N23: 12.7 | O23: 11 | P23: 3.2 | Q23: 0.1 | R23: 3 | S23: 3 | T23: 3 | U23: Yes | V23: 4 | W23: =COUNTIF($A$2:A23,A23) -> 1
A24: EMP0023 | B24: 45161 | D24: No | E24: 29 | F24: Non-Binary | G24: Divorced | H24: Master's | I24: Operations | J24: Operations Analyst | K24: 4 | L24: Hyderabad | M24: 108000 | N24: 9.4 | O24: 5.7 | P24: 2.4 | Q24: 0.4 | R24: 4 | S24: 4 | T24: 4 | U24: Yes | V24: 3 | W24: =COUNTIF($A$2:A24,A24) -> 1
A25: EMP0024 | B25: 45804 | D25: No | E25: 28 | F25: Female | G25: Married | H25: Diploma | I25: Data & Analytics | J25: Data Analyst | K25: 2 | L25: Bengaluru | M25: 59000 | N25: 7.4 | O25: 3.4 | P25: 0.6 | Q25: 0 | R25: 2 | S25: 4 | T25: 2 | U25: No | V25: 4 | W25: =COUNTIF($A$2:A25,A25) -> 1
... A33: EMP0032 | B33: 43572 | D33: No | E33: 37 | F33: Non-Binary | G33: Single | H33: Diploma | I33: Human Resources | J33: HR Manager | K33: 4 | L33: Mumbai | M33: 126000 | N33: 5 | O33: 8.8 | P33: 6.7 | Q33: 1.5 | R33: 4 | S33: 3 | T33: 4 | U33: No | V33: 4 | W33: =COUNTIF($A$2:A33,A33) -> 1
A34: EMP0033 | B34: 44478 | C34: 45854 | D34: Yes | E34: 34 | F34: Female | G34: Single | H34: Master's | I34: Technology | J34: QA Engineer | K34: 2 | L34: Mumbai | M34: 55000 | N34: 2.8 | O34: 9.3 | P34: 3.8 | Q34: 2.7 | R34: 2 | S34: 1 | T34: 3 | U34: No | V34: 4 | W34: =COUNTIF($A$2:A34,A34) -> 1
A35: EMP0034 | B35: 44129 | C35: 45838 | D35: Yes | E35: 26 | F35: Non-Binary | G35: Divorced | H35: Master's | I35: Finance | J35: Financial Analyst | K35: 1 | L35: Mumbai | M35: 39000 | N35: 5.3 | O35: 7.1 | P35: 4.7 | Q35: 1.8 | R35: 3 | S35: 4 | T35: 4 | U35: No | V35: 4 | W35: =COUNTIF($A$2:A35,A35) -> 1
A36: EMP0035 | B36: 45831 | D36: No | E36: 28 | F36: Female | G36: Divorced | H36: Bachelor's | I36: Data & Analytics | J36: Senior Data Analyst | K36: 2 | L36: Bengaluru | M36: 59000 | N36: 12.3 | O36: 1.8 | P36: 0.5 | Q36: 0 | R36: 3 | S36: 2 | T36: 3 | U36: No | V36: 1 | W36: =COUNTIF($A$2:A36,A36) -> 1
A37: EMP0036 | B37: 43940 | D37: No | E37: 35 | F37: Female | G37: Single | H37: PhD | I37: Operations | J37: Process Associate | K37: 2 | L37: Bengaluru | M37: 61000 | N37: 2.6 | O37: 8.3 | P37: 5.7 | Q37: 4.3 | R37: 3 | S37: 3 | T37: 3 | U37: Yes | V37: 4 | W37: =COUNTIF($A$2:A37,A37) -> 1
A38: EMP0037 | B38: 44417 | D38: No | E38: 35 | F38: Male | G38: Married | H38: Bachelor's | I38: Operations | J38: Operations Executive | K38: 5 | L38: Chennai | M38: 151000 | N38: 4.1 | O38: 10.4 | P38: 4.4 | Q38: 4.2 | R38: 4 | S38: 2 | T38: 1 | U38: No | V38: 2 | W38: =COUNTIF($A$2:A38,A38) -> 1
A39: EMP0038 | B39: 42636 | D39: No | E39: 37 | F39: Female | G39: Divorced | H39: PhD | I39: Data & Analytics | J39: Data Engineer | K39: 3 | L39: Mumbai | M39: 92000 | N39: 10 | O39: 10.2 | P39: 9.3 | Q39: 4.9 | R39: 3 | S39: 4 | T39: 2 | U39: Yes | V39: 1 | W39: =COUNTIF($A$2:A39,A39) -> 1
A40: EMP0039 | B40: 43971 | D40: No | E40: 28 | F40: Female | G40: Divorced | H40: PhD | I40: Operations | J40: Operations Analyst | K40: 1 | L40: Noida | M40: 34000 | N40: 10.2 | O40: 12.4 | P40: 5.6 | Q40: 3.4 | R40: 2 | S40: 2 | T40: 4 | U40: No | V40: 4 | W40: =COUNTIF($A$2:A40,A40) -> 1
A41: EMP0040 | B41: 44455 | C41: 45843 | D41: Yes | E41: 46 | F41: Non-Binary | G41: Married | H41: PhD | I41: Sales | J41: Sales Executive | K41: 3 | L41: Mumbai | M41: 81000 | N41: 4.2 | O41: 8.9 | P41: 3.8 | Q41: 3.1 | R41: 4 | S41: 3 | T41: 3 | U41: No | V41: 4 | W41: =COUNTIF($A$2:A41,A41) -> 1
A42: EMP0041 | B42: 45242 | D42: No | E42: 26 | F42: Female | G42: Married | H42: Master's | I42: Finance | J42: Finance Executive | K42: 1 | L42: Mumbai | M42: 42000 | N42: 13.6 | O42: 5.7 | P42: 2.1 | Q42: 1.6 | R42: 4 | S42: 3 | T42: 3 | U42: Yes | V42: 3 | W42: =COUNTIF($A$2:A42,A42) -> 1
A43: EMP0042 | B43: 44459 | D43: No | E43: 40 | F43: Male | G43: Divorced | H43: PhD | I43: Data & Analytics | J43: Senior Data Analyst | K43: 3 | L43: Noida | M43: 93000 | N43: 12.3 | O43: 4.4 | P43: 4.3 | Q43: 4.1 | R43: 3 | S43: 2 | T43: 3 | U43: No | V43: 3 | W43: =COUNTIF($A$2:A43,A43) -> 1
A44: EMP0043 | B44: 45846 | D44: No | E44: 31 | F44: Non-Binary | G44: Married | H44: Diploma | I44: Operations | J44: Process Associate | K44: 2 | L44: Noida | M44: 43000 | N44: 5.4 | O44: 5.8 | P44: 0.5 | Q44: 0 | R44: 3 | S44: 3 | T44: 3 | U44: No | V44: 5 | W44: =COUNTIF($A$2:A44,A44) -> 1
A45: EMP0044 | B45: 44928 | D45: No | E45: 32 | F45: Non-Binary | G45: Divorced | H45: Diploma | I45: Finance | J45: Finance Executive | K45: 2 | L45: Bengaluru | M45: 58000 | N45: 10.1 | O45: 10.6 | P45: 3 | Q45: 2.1 | R45: 3 | S45: 2 | T45: 3 | U45: No | V45: 3 | W45: =COUNTIF($A$2:A45,A45) -> 1
A46: EMP0045 | B46: 44371 | D46: No | E46: 33 | F46: Female | G46: Single | H46: Bachelor's | I46: IT Support | J46: System Administrator | K46: 2 | L46: Chennai | M46: 65000 | N46: 7.9 | O46: 4.9 | P46: 4.5 | Q46: 0.2 | R46: 3 | S46: 3 | T46: 4 | U46: No | V46: 4 | W46: =COUNTIF($A$2:A46,A46) -> 1
A47: EMP0046 | B47: 44457 | D47: No | E47: 37 | F47: Male | G47: Single | H47: Diploma | I47: Sales | J47: Business Development Executive | K47: 3 | L47: Bengaluru | M47: 69000 | N47: 4.7 | O47: 5.2 | P47: 4.3 | Q47: 0.3 | R47: 3 | S47: 3 | T47: 3 | U47: No | V47: 4 | W47: =COUNTIF($A$2:A47,A47) -> 1
...

Sheet Data_Dictionary
A1: Column | B1: Description
A2: Employee_ID | B2: Unique synthetic employee identifier
A3: Joining_Date | B3: Employee joining date
A4: Exit_Date | B4: Exit date; blank for employees still active
A5: Attrition | B5: Whether the employee left during the defined analysis period
A6: Age | B6: Employee age
A7: Gender | B7: Employee gender
A8: Marital_Status | B8: Marital status
A9: Education | B9: Highest education category
A10: Department | B10: Organizational department
A11: Job_Role | B11: Employee job role
A12: Job_Level | B12: Job seniority level from 1 to 5
... A23: Performance_Rating | B23: Performance rating from 1 to 5

Sheet Sheet3
A1: Employee_ID | B1: Joining_Date | C1: Exit_Date | D1: Attrition | E1: Age | F1: Gender | G1: Marital_Status | H1: Education | I1: Department | J1: Job_Role | K1: Job_Level | L1: Location | M1: Monthly_Salary | N1: Salary_Hike_Pct | O1: Total_Work_Experience | P1: Years_at_Company | Q1: Years_Since_Last_Promotion | R1: Job_Satisfaction | S1: Environment_Satisfaction | T1: Work_Life_Balance | U1: Overtime | V1: Performance_Rating | W1: Column1 | X1: Column2
A2: EMP0001 | B2: 44738 | D2: No | E2: 36 | F2: Non-Binary | G2: Divorced | H2: Bachelor's | I2: Operations | J2: Operations Executive | K2: 1 | L2: Chennai | M2: 30000 | N2: 11.6 | O2: 10.7 | P2: 3.5 | Q2: 0.3 | R2: 4 | S2: 3 | T2: 1 | U2: Yes | V2: 3 | W2: 1
A3: EMP0002 | B3: 43610 | D3: No | E3: 31 | F3: Male | G3: Married | H3: Bachelor's | I3: Data & Analytics | J3: Data Engineer | K3: 2 | L3: Hyderabad | M3: 59000 | N3: 15.3 | O3: 12.2 | P3: 6.6 | Q3: 2 | R3: 1 | S3: 2 | T3: 4 | U3: No | V3: 3 | W3: 1
A4: EMP0003 | B4: 43053 | D4: No | E4: 30 | F4: Non-Binary | G4: Single | H4: Bachelor's | I4: IT Support | J4: IT Analyst | K4: 3 | L4: Bengaluru | M4: 80000 | N4: 7.1 | O4: 11.2 | P4: 8.1 | Q4: 3.3 | R4: 3 | S4: 4 | T4: 3 | U4: No | V4: 4 | W4: 1
A5: EMP0004 | B5: 41703 | D5: No | E5: 35 | F5: Non-Binary | G5: Divorced | H5: Bachelor's | I5: Operations | J5: Operations Analyst | K5: 3 | L5: Chennai | M5: 55000 | N5: 2.1 | O5: 15.5 | P5: 11.8 | Q5: 5 | R5: 4 | S5: 2 | T5: 3 | U5: No | V5: 4 | W5: 1
A6: EMP0005 | B6: 44801 | D6: No | E6: 26 | F6: Male | G6: Single | H6: Bachelor's | I6: Operations | J6: Operations Analyst | K6: 1 | L6: Hyderabad | M6: 34000 | N6: 5.4 | O6: 10.7 | P6: 3.3 | Q6: 2.3 | R6: 3 | S6: 2 | T6: 3 | U6: Yes | V6: 4 | W6: 1
A7: EMP0006 | B7: 42011 | D7: No | E7: 43 | F7: Non-Binary | G7: Divorced | H7: Diploma | I7: Finance | J7: Finance Executive | K7: 1 | L7: Noida | M7: 33000 | N7: 9.3 | O7: 15 | P7: 11 | Q7: 5.3 | R7: 3 | S7: 3 | T7: 2 | U7: No | V7: 2 | W7: 1
A8: EMP0007 | B8: 44644 | D8: No | E8: 29 | F8: Female | G8: Divorced | H8: Bachelor's | I8: Human Resources | J8: HR Manager | K8: 4 | L8: Mumbai | M8: 107000 | N8: 4.4 | O8: 4.5 | P8: 3.8 | Q8: 0.2 | R8: 4 | S8: 2 | T8: 3 | U8: Yes | V8: 4 | W8: 1
A9: EMP0008 | B9: 42827 | D9: No | E9: 29 | F9: Female | G9: Single | H9: PhD | I9: Finance | J9: Finance Manager | K9: 3 | L9: Bengaluru | M9: 77000 | N9: 6.6 | O9: 14.2 | P9: 8.7 | Q9: 3.2 | R9: 1 | S9: 3 | T9: 3 | U9: No | V9: 2 | W9: 1
A10: EMP0009 | B10: 42657 | D10: No | E10: 33 | F10: Non-Binary | G10: Single | H10: Diploma | I10: Operations | J10: Operations Manager | K10: 5 | L10: Mumbai | M10: 134000 | N10: 12.3 | O10: 15.9 | P10: 9.2 | Q10: 3 | R10: 2 | S10: 2 | T10: 3 | U10: No | V10: 2 | W10: 1
A11: EMP0010 | B11: 42158 | C11: 45948 | D11: Yes | E11: 34 | F11: Male | G11: Single | H11: PhD | I11: Technology | J11: Software Developer | K11: 4 | L11: Chennai | M11: 107000 | N11: 3.7 | O11: 18 | P11: 10.4 | Q11: 0.5 | R11: 3 | S11: 3 | T11: 2 | U11: No | V11: 4 | W11: 1
A12: EMP0011 | B12: 43321 | D12: No | E12: 38 | F12: Non-Binary | G12: Married | H12: Bachelor's | I12: Data & Analytics | J12: Senior Data Analyst | K12: 3 | L12: Pune | M12: 91000 | N12: 8.5 | O12: 12.9 | P12: 7.4 | Q12: 4.3 | R12: 4 | S12: 3 | T12: 3 | U12: No | V12: 3 | W12: 1
A13: EMP0012 | B13: 45580 | C13: 45694 | D13: Yes | E13: 23 | F13: Non-Binary | G13: Single | H13: Diploma | I13: Data & Analytics | J13: Data Analyst | K13: 1 | L13: Noida | M13: 33000 | N13: 7.2 | O13: 6 | P13: 0.3 | Q13: 0 | R13: 2 | S13: 1 | T13: 1 | U13: No | V13: 3 | W13: 1
A14: EMP0013 | B14: 42822 | D14: No | E14: 35 | F14: Female | G14: Married | H14: Bachelor's | I14: Finance | J14: Accountant | K14: 3 | L14: Noida | M14: 64000 | N14: 10.3 | O14: 12.5 | P14: 8.8 | Q14: 2.4 | R14: 3 | S14: 2 | T14: 3 | U14: No | V14: 3 | W14: 1
A15: EMP0014 | B15: 43865 | D15: No | E15: 28 | F15: Male | G15: Married | H15: Bachelor's | I15: Operations | J15: Operations Executive | K15: 1 | L15: Bengaluru | M15: 37000 | N15: 13.1 | O15: 10.2 | P15: 5.9 | Q15: 0.8 | R15: 2 | S15: 2 | T15: 3 | U15: No | V15: 5 | W15: 1
A16: EMP0015 | B16: 43542 | D16: No | E16: 27 | F16: Female | G16: Married | H16: PhD | I16: Operations | J16: Operations Executive | K16: 1 | L16: Hyderabad | M16: 29000 | N16: 10.3 | O16: 10.7 | P16: 6.8 | Q16: 1.3 | R16: 4 | S16: 3 | T16: 1 | U16: No | V16: 3 | W16: 1
A17: EMP0016 | B17: 44862 | D17: No | E17: 30 | F17: Male | G17: Single | H17: Bachelor's | I17: Finance | J17: Finance Manager | K17: 2 | L17: Pune | M17: 53000 | N17: 4.6 | O17: 9.2 | P17: 3.2 | Q17: 0.2 | R17: 3 | S17: 3 | T17: 3 | U17: No | V17: 4 | W17: 1
A18: EMP0017 | B18: 44908 | D18: No | E18: 39 | F18: Female | G18: Single | H18: Diploma | I18: Technology | J18: Software Developer | K18: 3 | L18: Pune | M18: 99000 | N18: 8.7 | O18: 7.8 | P18: 3 | Q18: 1.9 | R18: 4 | S18: 3 | T18: 3 | U18: Yes | V18: 4 | W18: 1
A19: EMP0018 | B19: 43154 | D19: No | E19: 36 | F19: Non-Binary | G19: Married | H19: Master's | I19: Sales | J19: Business Development Executive | K19: 2 | L19: Hyderabad | M19: 47000 | N19: 10.4 | O19: 7.9 | P19: 7.9 | Q19: 3.7 | R19: 4 | S19: 3 | T19: 2 | U19: No | V19: 4 | W19: 1
A20: EMP0019 | B20: 45239 | D20: No | E20: 33 | F20: Non-Binary | G20: Single | H20: Master's | I20: Technology | J20: Senior Software Developer | K20: 2 | L20: Hyderabad | M20: 73000 | N20: 0 | O20: 10 | P20: 2.1 | Q20: 1.4 | R20: 3 | S20: 1 | T20: 4 | U20: No | V20: 3 | W20: 1
A21: EMP0020 | B21: 45249 | D21: No | E21: 34 | F21: Male | G21: Single | H21: PhD | I21: Technology | J21: Software Developer | K21: 3 | L21: Hyderabad | M21: 84000 | N21: 9.4 | O21: 7.6 | P21: 2.1 | Q21: 1.8 | R21: 2 | S21: 3 | T21: 2 | U21: No | V21: 5 | W21: 1
A22: EMP0021 | B22: 45402 | D22: No | E22: 31 | F22: Male | G22: Divorced | H22: Bachelor's | I22: Technology | J22: Software Developer | K22: 2 | L22: Hyderabad | M22: 63000 | N22: 14.9 | O22: 7.3 | P22: 1.7 | Q22: 1 | R22: 2 | S22: 2 | T22: 4 | U22: No | V22: 4 | W22: 1
A23: EMP0022 | B23: 44861 | D23: No | E23: 27 | F23: Female | G23: Divorced | H23: PhD | I23: Human Resources | J23: Recruiter | K23: 1 | L23: Chennai | M23: 28000 | N23: 12.7 | O23: 11 | P23: 3.2 | Q23: 0.1 | R23: 3 | S23: 3 | T23: 3 | U23: Yes | V23: 4 | W23: 1
A24: EMP0023 | B24: 45161 | D24: No | E24: 29 | F24: Non-Binary | G24: Divorced | H24: Master's | I24: Operations | J24: Operations Analyst | K24: 4 | L24: Hyderabad | M24: 108000 | N24: 9.4 | O24: 5.7 | P24: 2.4 | Q24: 0.4 | R24: 4 | S24: 4 | T24: 4 | U24: Yes | V24: 3 | W24: 1
A25: EMP0024 | B25: 45804 | D25: No | E25: 28 | F25: Female | G25: Married | H25: Diploma | I25: Data & Analytics | J25: Data Analyst | K25: 2 | L25: Bengaluru | M25: 59000 | N25: 7.4 | O25: 3.4 | P25: 0.6 | Q25: 0 | R25: 2 | S25: 4 | T25: 2 | U25: No | V25: 4 | W25: 1
... A33: EMP0032 | B33: 43572 | D33: No | E33: 37 | F33: Non-Binary | G33: Single | H33: Diploma | I33: Human Resources | J33: HR Manager | K33: 4 | L33: Mumbai | M33: 126000 | N33: 5 | O33: 8.8 | P33: 6.7 | Q33: 1.5 | R33: 4 | S33: 3 | T33: 4 | U33: No | V33: 4 | W33: 1
A34: EMP0033 | B34: 44478 | C34: 45854 | D34: Yes | E34: 34 | F34: Female | G34: Single | H34: Master's | I34: Technology | J34: QA Engineer | K34: 2 | L34: Mumbai | M34: 55000 | N34: 2.8 | O34: 9.3 | P34: 3.8 | Q34: 2.7 | R34: 2 | S34: 1 | T34: 3 | U34: No | V34: 4 | W34: 1
A35: EMP0034 | B35: 44129 | C35: 45838 | D35: Yes | E35: 26 | F35: Non-Binary | G35: Divorced | H35: Master's | I35: Finance | J35: Financial Analyst | K35: 1 | L35: Mumbai | M35: 39000 | N35: 5.3 | O35: 7.1 | P35: 4.7 | Q35: 1.8 | R35: 3 | S35: 4 | T35: 4 | U35: No | V35: 4 | W35: 1
A36: EMP0035 | B36: 45831 | D36: No | E36: 28 | F36: Female | G36: Divorced | H36: Bachelor's | I36: Data & Analytics | J36: Senior Data Analyst | K36: 2 | L36: Bengaluru | M36: 59000 | N36: 12.3 | O36: 1.8 | P36: 0.5 | Q36: 0 | R36: 3 | S36: 2 | T36: 3 | U36: No | V36: 1 | W36: 1
A37: EMP0036 | B37: 43940 | D37: No | E37: 35 | F37: Female | G37: Single | H37: PhD | I37: Operations | J37: Process Associate | K37: 2 | L37: Bengaluru | M37: 61000 | N37: 2.6 | O37: 8.3 | P37: 5.7 | Q37: 4.3 | R37: 3 | S37: 3 | T37: 3 | U37: Yes | V37: 4 | W37: 1
A38: EMP0037 | B38: 44417 | D38: No | E38: 35 | F38: Male | G38: Married | H38: Bachelor's | I38: Operations | J38: Operations Executive | K38: 5 | L38: Chennai | M38: 151000 | N38: 4.1 | O38: 10.4 | P38: 4.4 | Q38: 4.2 | R38: 4 | S38: 2 | T38: 1 | U38: No | V38: 2 | W38: 1
A39: EMP0038 | B39: 42636 | D39: No | E39: 37 | F39: Female | G39: Divorced | H39: PhD | I39: Data & Analytics | J39: Data Engineer | K39: 3 | L39: Mumbai | M39: 92000 | N39: 10 | O39: 10.2 | P39: 9.3 | Q39: 4.9 | R39: 3 | S39: 4 | T39: 2 | U39: Yes | V39: 1 | W39: 1
A40: EMP0039 | B40: 43971 | D40: No | E40: 28 | F40: Female | G40: Divorced | H40: PhD | I40: Operations | J40: Operations Analyst | K40: 1 | L40: Noida | M40: 34000 | N40: 10.2 | O40: 12.4 | P40: 5.6 | Q40: 3.4 | R40: 2 | S40: 2 | T40: 4 | U40: No | V40: 4 | W40: 1
A41: EMP0040 | B41: 44455 | C41: 45843 | D41: Yes | E41: 46 | F41: Non-Binary | G41: Married | H41: PhD | I41: Sales | J41: Sales Executive | K41: 3 | L41: Mumbai | M41: 81000 | N41: 4.2 | O41: 8.9 | P41: 3.8 | Q41: 3.1 | R41: 4 | S41: 3 | T41: 3 | U41: No | V41: 4 | W41: 1
A42: EMP0041 | B42: 45242 | D42: No | E42: 26 | F42: Female | G42: Married | H42: Master's | I42: Finance | J42: Finance Executive | K42: 1 | L42: Mumbai | M42: 42000 | N42: 13.6 | O42: 5.7 | P42: 2.1 | Q42: 1.6 | R42: 4 | S42: 3 | T42: 3 | U42: Yes | V42: 3 | W42: 1
A43: EMP0042 | B43: 44459 | D43: No | E43: 40 | F43: Male | G43: Divorced | H43: PhD | I43: Data & Analytics | J43: Senior Data Analyst | K43: 3 | L43: Noida | M43: 93000 | N43: 12.3 | O43: 4.4 | P43: 4.3 | Q43: 4.1 | R43: 3 | S43: 2 | T43: 3 | U43: No | V43: 3 | W43: 1
A44: EMP0043 | B44: 45846 | D44: No | E44: 31 | F44: Non-Binary | G44: Married | H44: Diploma | I44: Operations | J44: Process Associate | K44: 2 | L44: Noida | M44: 43000 | N44: 5.4 | O44: 5.8 | P44: 0.5 | Q44: 0 | R44: 3 | S44: 3 | T44: 3 | U44: No | V44: 5 | W44: 1
A45: EMP0044 | B45: 44928 | D45: No | E45: 32 | F45: Non-Binary | G45: Divorced | H45: Diploma | I45: Finance | J45: Finance Executive | K45: 2 | L45: Bengaluru | M45: 58000 | N45: 10.1 | O45: 10.6 | P45: 3 | Q45: 2.1 | R45: 3 | S45: 2 | T45: 3 | U45: No | V45: 3 | W45: 1
A46: EMP0045 | B46: 44371 | D46: No | E46: 33 | F46: Female | G46: Single | H46: Bachelor's | I46: IT Support | J46: System Administrator | K46: 2 | L46: Chennai | M46: 65000 | N46: 7.9 | O46: 4.9 | P46: 4.5 | Q46: 0.2 | R46: 3 | S46: 3 | T46: 4 | U46: No | V46: 4 | W46: 1
A47: EMP0046 | B47: 44457 | D47: No | E47: 37 | F47: Male | G47: Single | H47: Diploma | I47: Sales | J47: Business Development Executive | K47: 3 | L47: Bengaluru | M47: 69000 | N47: 4.7 | O47: 5.2 | P47: 4.3 | Q47: 0.3 | R47: 3 | S47: 3 | T47: 3 | U47: No | V47: 4 | W47: 1
...

Sheet PT_Attrition
A3: Row Labels | B3: Average of Attrition_Flag
A4: Data & Analytics | B4: 0.13761468
A5: Finance | B5: 0.13235294
A6: Human Resources | B6: 0.16086957
A7: It Support | B7: 0.13888889
A8: Operations | B8: 0.17889908
A9: Sales | B9: 0.20618557
A10: Technology | B10: 0.15909091
A11: Grand Total | B11: 0.15866667
A14: Row Labels | B14: Average of Attrition_Flag
A15: 18-25 | B15: 0.23036649
A16: 26-35 | B16: 0.14756258
A17: 36-45 | B17: 0.14545455
A18: 46-55 | B18: 0.16666667
A19: 56+ | B19: 1
A20: Grand Total | B20: 0.15866667
